<?xml version="1.0" encoding="utf-8"?>
<!-- This URDF was automatically created by SolidWorks to URDF Exporter! Originally created by Stephen Brawner (brawner@gmail.com) 
     Commit Version: 1.6.0-4-g7f85cfe  Build Version: 1.6.7995.38578
     For more information, please see http://wiki.ros.org/sw_urdf_exporter -->
<robot name="robot_2" xmlns:xacro="http://www.ros.org/wiki/xacro">
    <link name="base_link">
  
    </link>
    
    <link name="base_footprint">
  
      </link>

      <joint name="base_footprint_joint">
        <origin xyz="0 0 0" rpy="0 0 0"/>
        <parent link="base_link"/>
        <child link="base_footprint"/>
      </joint>


    <link name="chassis_link">
        <inertial>
            <origin xyz="-0.028695 0.11375 -0.02283" rpy="0 0 0" />
      <mass value="3.7262" />
      <inertia ixx="0.14393" ixy="8.3238E-18" ixz="4.858E-17" iyy="0.28646" iyz="-4.6184E-20" izz="0.14393" />
    </inertial>
    <visual>
      <origin xyz="0 0 0" rpy="0 0 0" />
      <geometry>
        <mesh
          filename="package://robot_2/meshes/base_link.STL" />
      </geometry>
      <material
        name="">
        <color
          rgba="0.79216 0.81961 0.93333 1" />
      </material>
    </visual>
    <collision>
      <origin
        xyz="0 0 0"
        rpy="0 0 0" />
      <geometry>
        <mesh
          filename="package://robot_2/meshes/base_link.STL" />
      </geometry>
    </collision>
  </link>

  
  <link
    name="front_right_wheel">
    <inertial>
      <origin
        xyz="0 0 0"
        rpy="0 0 0" />
      <mass
        value="0.69378" />
      <inertia
        ixx="0.0010914"
        ixy="-2.9867E-19"
        ixz="-5.9631E-19"
        iyy="0.0010914"
        iyz="-1.1472E-19"
        izz="0.0020123" />
    </inertial>
    <visual>
      <origin
        xyz="0 0 0"
        rpy="0 0 0" />
      <geometry>
        <mesh
          filename="package://robot_2/meshes/front_right_wheel.STL" />
      </geometry>
      <material
        name="">
        <color
          rgba="0.79216 0.81961 0.93333 1" />
      </material>
    </visual>
    <collision>
      <origin
        xyz="0 0 0"
        rpy="0 0 0" />
      <geometry>
        <mesh
          filename="package://robot_2/meshes/front_right_wheel.STL" />
      </geometry>
    </collision>
  </link>
  <joint
    name="front_right_wheel_joint"
    type="continuous">
    <origin
      xyz="0.18996 -0.19583 0.076579"
      rpy="1.5708 0 0.7854" />
    <parent
      link="chassis_link" />
    <child
      link="front_right_wheel" />
    <axis
      xyz="0 0 -1" />
    <limit
      lower="0"
      upper="0"
      effort="300"
      velocity="3" />
  </joint>
  <link
    name="front_left_wheel">
    <inertial>
      <origin
        xyz="0 -1.3878E-17 5.5511E-17"
        rpy="0 0 0" />
      <mass
        value="0.69378" />
      <inertia
        ixx="0.0010914"
        ixy="3.9272E-20"
        ixz="3.7947E-19"
        iyy="0.0010914"
        iyz="1.7071E-18"
        izz="0.0020123" />
    </inertial>
    <visual>
      <origin
        xyz="0 0 0"
        rpy="0 0 0" />
      <geometry>
        <mesh
          filename="package://robot_2/meshes/front_left_wheel.STL" />
      </geometry>
      <material
        name="">
        <color
          rgba="0.79216 0.81961 0.93333 1" />
      </material>
    </visual>
    <collision>
      <origin
        xyz="0 0 0"
        rpy="0 0 0" />
      <geometry>
        <mesh
          filename="package://robot_2/meshes/front_left_wheel.STL" />
      </geometry>
    </collision>
  </link>
  <joint
    name="front_left_wheel_joint"
    type="continuous">
    <origin
      xyz="0.18996 0.24149 0.076579"
      rpy="-1.5708 0 -0.7854" />
    <parent
      link="chassis_link" />
    <child
      link="front_left_wheel" />
    <axis
      xyz="0 0 -1" />
    <limit
      lower="0"
      upper="0"
      effort="600"
      velocity="3" />
  </joint>
  <link
    name="back_left_wheel">
    <inertial>
      <origin
        xyz="-3.2641E-14 -5.2888E-14 -4.6629E-15"
        rpy="0 0 0" />
      <mass
        value="0.69378" />
      <inertia
        ixx="0.0010914"
        ixy="1.3844E-20"
        ixz="1.301E-18"
        iyy="0.0010914"
        iyz="2.0367E-18"
        izz="0.0020123" />
    </inertial>
    <visual>
      <origin
        xyz="0 0 0"
        rpy="0 0 0" />
      <geometry>
        <mesh
          filename="package://robot_2/meshes/back_left_wheel.STL" />
      </geometry>
      <material
        name="">
        <color
          rgba="0.79216 0.81961 0.93333 1" />
      </material>
    </visual>
    <collision>
      <origin
        xyz="0 0 0"
        rpy="0 0 0" />
      <geometry>
        <mesh
          filename="package://robot_2/meshes/back_left_wheel.STL" />
      </geometry>
    </collision>
  </link>
  <joint
    name="back_left_wheel_joint"
    type="continuous">
    <origin
      xyz="-0.24736 0.24149 0.076579"
      rpy="-1.5708 0 0.7854" />
    <parent
      link="chassis_link" />
    <child
      link="back_left_wheel" />
    <axis
      xyz="0 0 -1" />
    <limit
      lower="0"
      upper="0"
      effort="600"
      velocity="3" />
  </joint>
  <link
    name="back_right_wheel">
    <inertial>
      <origin
        xyz="-4.4076E-14 -5.5678E-14 6.1062E-16"
        rpy="0 0 0" />
      <mass
        value="0.69378" />
      <inertia
        ixx="0.0010914"
        ixy="-2.2471E-19"
        ixz="1.6263E-18"
        iyy="0.0010914"
        iyz="1.9778E-18"
        izz="0.0020123" />
    </inertial>
    <visual>
      <origin
        xyz="0 0 0"
        rpy="0 0 0" />
      <geometry>
        <mesh
          filename="package://robot_2/meshes/back_right_wheel.STL" />
      </geometry>
      <material
        name="">
        <color
          rgba="0.79216 0.81961 0.93333 1" />
      </material>
    </visual>
    <collision>
      <origin
        xyz="0 0 0"
        rpy="0 0 0" />
      <geometry>
        <mesh
          filename="package://robot_2/meshes/back_right_wheel.STL" />
      </geometry>
    </collision>
  </link>
  <joint
    name="back_right_wheel_joint"
    type="continuous">
    <origin
      xyz="-0.24736 -0.19583 0.076579"
      rpy="1.5708 0 -0.7854" />
    <parent
      link="chassis_link" />
    <child
      link="back_right_wheel" />
    <axis
      xyz="0 0 -1" />
    <limit
      lower="0"
      upper="0"
      effort="600"
      velocity="3" />
  </joint>
</robot>
